Workbook
Name _bookmark56: '32 Cadre L ogiqueBfssam 1er'!$D$3
Name _bookmark58: '32 Cadre L ogiqueBfssam 1er'!#REF!
Name _bookmark59: '32 Cadre L ogiqueBfssam 1er'!#REF!
Name _bookmark60: '32 Cadre L ogiqueBfssam 1er'!#REF!
Name _bookmark61: '32 Cadre L ogiqueBfssam 1er'!#REF!
Name _bookmark62: '32 Cadre L ogiqueBfssam 1er'!#REF!
Name _bookmark63: '32 Cadre L ogiqueBfssam 1er'!#REF!
Name _bookmark64: '32 Cadre L ogiqueBfssam 1er'!#REF!
Name _bookmark66: '32 Cadre L ogiqueBfssam 1er'!#REF!
Name _bookmark67: '32 Cadre L ogiqueBfssam 1er'!#REF!
Name _bookmark68: '32 Cadre L ogiqueBfssam 1er'!#REF!
Name _bookmark69: '32 Cadre L ogiqueBfssam 1er'!#REF!
Name _bookmark70: '32 Cadre L ogiqueBfssam 1er'!#REF!
Name _bookmark72: '32 Cadre L ogiqueBfssam 1er'!#REF!
Name _bookmark73: '32 Cadre L ogiqueBfssam 1er'!#REF!
Name _bookmark75: '32 Cadre L ogiqueBfssam 1er'!#REF!
Name _bookmark76: '32 Cadre L ogiqueBfssam 1er'!#REF!
Name _bookmark77: '32 Cadre L ogiqueBfssam 1er'!#REF!
Name _bookmark78: '32 Cadre L ogiqueBfssam 1er'!#REF!
Name _bookmark79: '32 Cadre L ogiqueBfssam 1er'!#REF!
Name _bookmark80: '32 Cadre L ogiqueBfssam 1er'!#REF!
Name _bookmark81: '32 Cadre L ogiqueBfssam 1er'!#REF!
Name _bookmark82: '32 Cadre L ogiqueBfssam 1er'!#REF!
Name _bookmark83: '32 Cadre L ogiqueBfssam 1er'!#REF!
Name _bookmark84: '32 Cadre L ogiqueBfssam 1er'!#REF!
Name _bookmark85: '32 Cadre L ogiqueBfssam 1er'!#REF!
Name _bookmark86: '32 Cadre L ogiqueBfssam 1er'!#REF!

Sheet 32 Cadre L ogiqueBfssam 1er
D2: 5.1 CADRE LOGIQUE PAR SECTEUR
D3: 5.1.1 CADRE LOGIQUE DE L’INSTITUTION COMMUNALE Tableau 9: Cadre logique de l’institution communale
B5: Chapitre: | C5: Problème central : | E5: Logique d’intervention | F5: Indicateur objectivement vérifiable | G5: Source de vérification | H5: Hypothèse de réalisation
B6: Institution communale | C6: Difficulté à rendre véritablement opérationnelle l’institution communale | D6: Objectif global | E6: Rendre plus opérationnel l’institution communale
D7: Objectifs spécifiques | E7: 1-Améliorer le système opérationnel de la Commune par la construction d’un bâtiment, l’acquisition de deux véhicules et la mise sur pied d’une police municipale | F7: Un bâtiment de l’hôtel de ville construit et opérationnel. Véhicules de fonction et de relais disponibles. Organigramme adapté et opérationnel. Services pourvus en personnel et fonctionnels | G7: Visite du bâtiment, PV de réception, Photos, Consultation du site web,Archives de la Commune. Fichier du patrimoine communal. Archives de la commune. Actes de recrutement, Attestation de service | H7: Finances disponibles et sites sécurisés19/08/2024. Volonté de l’exécutif Communal
E8: 2-Améliorer les stratégies d’accroissement des recettes de la Commune | F8: Plate-forme de concertation fonctionnelle. Engin lourd et camions acquis et mis en fonction. Recette communale augmenté à au moins 20%. Les tâches sont claires et précises dans chaque service et pour chaque membre du personnel | G8: Compte administratif approuvé19/08/2024. Cadre juridique signé par les parties. Dossier d’acquisitio. Présence de l’engin lourd. Prestations effectuées. Rapport des réunions. Organigramme fonctionnel. Fiche de présence. Contrats de recrutement | H8: Volonté de l’Exécutif communal. Bonne gouvernance au niveau de l’utilisation de l’engin. Bonne gouvernance au niveau du personnel de recouvrement. Engagement des parties prenantes. Finances disponibles
E9: 3- Doter la commune de 02 engins lourds et 02 camions en vue d’augmenter de 50 % au moins le niveau de prestation de service au sein de l’institution communale et en redynamisant les services de la commune | F9: Engin lourd acquis et mis en fonction. Les tâches sont claires et précises dans chaque service et pour chaque membre du personnel | G9: Dossier d’acquisition. Présence de l’engin lourd. Prestations effectuées. Contrats de recrutement. Organigramme fonctionnel | H9: Finances disponibles. Bonne gouvernance dans l’utilisation de l’engin
D10: Résultats | E10: R1O1- Un bâtiment approprié est construit et équipé pour abriter les services de la commune | F10: Bâtiment construit | G10: Visite du bâtiment | H10: Disponibilité d’une source de financement et Disponibilité du site sécurisé
E11: R2O1-Une police municipale est opérationnelle | F11: Police communale opérationnelle | G11: Actes de recrutement. Attestation de service | H11: Volonté de l’Exécutif Communal
E13: R3O1- Un Véhicule de fonction et 02 véhicules de relais sont disponibles dans la commune | F13: 01 Véhicule de fonction et 02 véhicules de relais | G13: De visu | H13: Disponibilité d’une source de financement
E14: R4O1- Les services de la commune sont redynamisés au regard de l’organigramme | F14: Organigramme adapté et opérationnel. -Services pourvus en personnel et fonctionnels | G14: Archives de la commune | H14: Volonté de l’exécutif Communal
E15: R1O2- Deux plates-formes de concertation sont mises en place et sont opérationnelles au sein de l’institution communale | F15: Plates formes fonctionnelles | G15: Texte de base | H15: Idem
E16: R2O2-Les recettes communales ont augmenté au moins de 20 % | F16: Le niveau de réalisation des recettes de la commune s’est augmenté de 20% | G16: Compte administratif approuvé | H16: Volonté de l’Exécutif Communal
E17: R3O2-Les services au sein de l’institution communale sont redynamisés et offre une prestation de qualité aux populations de la commune. | F17: . Réduction de 50% des délais de traitement des dossiers Degré de satisfaction des usagers et des populationsDynamique au sein de l’institution. Célérité dans les traitements des dossiers | G17: Rapport d’activités et manuel de procédure | H17: Volonté de l’Exécutif Communal
E18: R1O3 engins lourds et 02 camions bennes sont acquis pour assurer les prestations de la commune | F18: 02 engins lourds et 02 camions opérationnels | G18: In situ | H18: -Disponibilité d’une source de financement
D19: Activités | F19: Tâches/Moyens | G19: Coût | H19: Conditions préalables de réalisation
E20: A1R1O1- Identifier et acquérir un site d’au moins 2000 M2pour la construction de l’hôtel de ville de Bafoussam 1er | F20: Achat et sécurisation d’un site d’au moins 2000 M2 | G20: 50000000 | H20: Site sécurisé et finances disponibles
E21: A2R1O1-Faire le plan de construction de l’hôtel de ville | F21: Réalisation du plan de construction des infrastructures | G21: PM (voir coût de faisabilité) | H21: Existence de terrain
E22: A3R1O1- Mobiliser les fonds pour la construction du bâtiment de l’hôtel de ville | F22: Rechercher les partenariats et solliciter les contributions des élites | G22: 1000000 | H22: Disponibilité des financements
E23: A4R1O1 Construire et équiper l’hôtel de ville de Bafoussam Ier (Prévoir les rampes pour les handicapés) | F23: DAO et PPM | G23: 43750000 | H23: Disponibilité du site sécurisé et Disponibilité d’une source de financement
F24: Etudes de faisabilités technique et environnementale | G24: 87500000 | H24: Idem
F25: Exécution des travaux de construction (Matériaux, main d’œuvre) | G25: 700000000 | H25: Idem
F26: Suivis/contrôle des travaux | G26: 43750000 | H26: Idem
E27: S/s-total R1O1 | F27: 1 | G27: =SUM(G22:G26)+G20 -> 926000000
E28: A1R2O1 Doter la commune de 01 Véhicule de fonction et de 02 véhiculesde relais | F28: Elaborer DAO et PPM | G28: 4500000
F29: Achat et réception | G29: 85500000
E30: S/s-total R201 | F30: 1 | G30: =SUM(G28:G29) -> 90000000 | H30: Idem
E31: A1R3O1-Mettre sur pied une police municipale avec traitement annuel | F31: Recruter, former et équiper le personnel de cette police | G31: 30000000 | H31: Volonté de l’Exécutif Communal et disponibilité financière
E32: S/s-total R301 | F32: 1 | G32: =SUM(G31) -> 30000000
E33: A1R4O1- Elaborer et adapter l’organigramme des services de la commune | F33: Recruter une personne ressource | G33: 50000 | H33: Idem
F34: Tenir un atelier pour la description des tâches aux postes et la restructuration des services | G34: 200000 | H34: Restructuration des services
E35: A2R4O1- Nommer les responsables dans les postes définis dans l’organigramme des services | F35: Etablir une décision communale de nomination | G35: PM | H35: Volonté de l’Exécutif communal
E36: A3R4O1- Organiser les réunions de coordination de service | F36: Préparer et inviter toutes les parties prenantes | G36: PM | H36: Suivi rigoureux du chronogramme des activités
E37: A4R4O1- Actualiser en début de chaque année le cahier de charges de chaque service au sein de l’institution communale | F37: Préparer et inviter toutes les parties prenantes | G37: PM | H37: Implication des tous les acteurs
E38: A5R4O1- Organiser chaque fin d’année une réunion bilan des activités de l’institution communale | F38: Préparer et inviter toutes les parties prenantes | G38: PM | H38: Implication des tous les acteurs
E39: S/s-total R401 | F39: 1 | G39: 500250000
E40: A1R1O2- Organiser quatre assemblées constitutives pour les plates formes Institution Communale et sectoriels et institution communale et opérateurs économiques | F40: Recruter des personnes ressources pour les formations | G40: 200000 | H40: Existence formelle du cadre de concertation
E41: A2R1O2- Organiser les réunions dans les différentes plates formes de concertation | F41: Préparer et tenir quatre ateliers | G41: 1800000 | H41: Disponibilité financières
E42: A3R1O2- Identifier et viabiliser toutes les sources potentielles de richesses répertoriées dans l’espace géographique de la commune | F42: Recruter les personnes ressources | G42: 5000000 | H42: Doter la commune d’un fichier de contribuable fiable
F43: Réaliser une cartographie des ressources avec les coordonnées GPS | G43: 10000000
...

Sheet 33. Coût estimatif du PCD
B1: Tableau 33 : Coût estimatif des PCD
A3: N° | B3: Secteur | C3: BABADJOU Montant (en F CFA) | D3: MBOUDA Montant (en F CFA) | E3: BAFOUSSAM 3 Montant (en F CFA) | F3: BAFOUSSAM 2 Montant (en F CFA) | G3: BAFOUSSAM 1 Montant (en F CFA) | H3: BAFANG Montant (en F CFA) | I3: BAKOU Montant (en F CFA) | J3: BANA Montant (en F CFA) | K3: BANDJA Montant (en F CFA) | L3: BANKA Montant (en F CFA) | M3: BANWA Montant (en F CFA) | N3: KEKEM Montant (en F CFA) | O3: BANGANTE Montant (en F CFA) | P3: BANGOU Montant (en F CFA) | Q3: BASSAMBA Montant (en F CFA) | R3: BAZOU Montant (en F CFA) | S3: TONGA Montant (en F CFA) | T3: BAHAM Montant (en F CFA) | U3: BAMENDJOU Montant (en F CFA) | V3: BATIE Montant (en F CFA) | W3: BAYANGAM Montant (en F CFA) | X3: DSCHANG Montant (en F CFA) | Y3: FOKOUE Montant (en F CFA) | Z3: FONGO-TONGO Montant (en F CFA) | AA3: FOUMBOT Montant (en F CFA) | AB3: KOUTABA Montant (en F CFA) | AC3: TOTAL OUEST
B4: Année du PCD | H4: 2013 | I4: 2015 | J4: 2015 | K4: 2014 | L4: 2014 | M4: 2015
A5: 1 | B5: Institutuion communale | C5: 0 | D5: 200000000 | E5: 386500000 | F5: 229000000 | G5: ='32 Cadre L ogiqueBfssam 1er'!$G$51 -> 1974000000 | H5: 24593600000 | I5: 225000000 | J5: 309650000 | K5: 45500000 | L5: 4895500000 | M5: 4459500000 | N5: 170800000 | O5: 724950000 | P5: 1506600000 | Q5: 417100000 | R5: 158600000 | S5: 470750984 | T5: 1626600000 | U5: 157140000 | V5: 165800000 | X5: 137350000 | Y5: 514100000 | Z5: 152700000 | AA5: 184940000 | AC5: =SUM(C5:AB5) -> 43705680984
A6: =A5+1 -> 2 | B6: Agriculture | C6: 2764679868 | D6: 3534600000 | E6: 299630000 | F6: 781140000 | G6: ='32 Cadre L ogiqueBfssam 1er'!$G$83 -> 206100000 | H6: 179300000 | I6: 2079700000 | J6: 1674500000 | K6: 499000000 | L6: 791150000 | M6: 551150000 | N6: 655375000 | O6: 1719700000 | P6: 307100000 | Q6: 223000000 | R6: 146730000 | S6: 1223000000 | T6: 604600000 | U6: 1694864000 | V6: 76700000 | W6: 69600000 | X6: 48800000 | Y6: 211950000 | Z6: 604020000 | AA6: 1081100000 | AB6: 1885353700 | AC6: =SUM(C6:AB6) -> 23912842568
A7: =A6+1 -> 3 | B7: Elevage et pêche et industrie animale | C7: 1217720000 | D7: 1153800000 | E7: 164000000 | F7: 522050000 | G7: ='32 Cadre L ogiqueBfssam 1er'!$G$106 -> 106210000 | H7: 143000000 | I7: 146700000 | J7: 677000000 | K7: 465315000 | L7: 601000000 | M7: 201250000 | N7: 23200000 | O7: 1005000000 | P7: 121650000 | Q7: 136000000 | R7: 27430000 | S7: 170000000 | T7: 249500000 | U7: 822400000 | V7: 57200000 | W7: 58820000 | X7: 17200000 | Y7: 76130000 | Z7: 155000000 | AA7: 401350000 | AB7: 508500000 | AC7: =SUM(C7:AB7) -> 9227425000
A8: =A7+1 -> 4 | B8: Santé publique | C8: 346821135 | D8: 146500000 | E8: 1015600000 | F8: 490050000 | G8: ='32 Cadre L ogiqueBfssam 1er'!$G$142 -> 635150000 | H8: 161978740 | I8: 318500000 | J8: 331000000 | K8: 994900000 | L8: 570300000 | M8: 266300000 | N8: 301050000 | O8: 739000000 | P8: 150878000 | Q8: 94500000 | R8: 329560000 | S8: 532000000 | T8: 218980000 | U8: 1011515390 | V8: 154550000 | W8: 134700000 | X8: 1394129600 | Y8: 801800000 | Z8: 333000000 | AA8: 1337540000 | AB8: 2022200000 | AC8: =SUM(C8:AB8) -> 14832502865
A9: =A8+1 -> 5 | B9: Education de base | C9: 2880524120 | D9: 4151562000 | E9: 1954630000 | F9: 1180560000 | G9: ='32 Cadre L ogiqueBfssam 1er'!$G$298 -> 1070520000 | H9: 1148716800 | I9: 1112000000 | J9: 739660000 | K9: 130356192000 | L9: 988875000 | M9: 688975000 | N9: 1075000000 | O9: 3385000000 | P9: 447002000 | Q9: 190200000 | R9: 1295390000 | S9: 2305865 | T9: 1478500000 | U9: 1797761420 | V9: 292579000 | W9: 491500000 | X9: 1111000000 | Y9: 713940000 | Z9: 2329470000 | AA9: 3913204000 | AB9: 3832770800 | AC9: =SUM(C9:AB9) -> 168627838005
A10: =A9+1 -> 6 | B10: Enseignement secondaire | C10: 568777521 | D10: 3444750000 | E10: 2981775000 | F10: 878600000 | G10: ='32 Cadre L ogiqueBfssam 1er'!$G$521 -> 1151840000 | H10: 2579658400 | I10: 357800000 | J10: 1508600000 | K10: 1181636000 | L10: 861500000 | M10: 661500000 | N10: 552200000 | O10: 11761500000 | P10: 1442000000 | Q10: 129000000 | R10: 1212200000 | S10: 201600000 | T10: 650560000 | U10: 1561138000 | V10: 197020000 | W10: 353540000 | X10: 3294250000 | Y10: 873490000 | Z10: 1231940000 | AA10: 572680000 | AB10: 2469426000 | AC10: =SUM(C10:AB10) -> 42678980921
A11: =A10+1 -> 7 | B11: Travaux publics | C11: 730798864 | E11: 25877750000 | F11: 20510800000 | G11: ='32 Cadre L ogiqueBfssam 1er'!$G$199 -> 7987750000 | H11: 4599100000 | I11: 2190000000 | J11: 5177400000 | K11: 610000000 | L11: 1375866000 | M11: 1233666000 | N11: 2185600000 | O11: 19670200000 | P11: 2266500000 | Q11: 671595295 | R11: 1750900000 | S11: 81201083 | T11: 2298000000 | U11: 11833900026 | V11: 583900000 | W11: 875000000 | X11: 429500000 | Y11: 1178140000 | Z11: 493500000 | AA11: 403250000 | AB11: 3988390000 | AC11: =SUM(C11:AB11) -> 119002707268
A12: 1 | B12: Jeunesse et éducation Civique | C12: 90070000 | D12: 210250000 | E12: 661400000 | F12: 214000000 | G12: ='32 Cadre L ogiqueBfssam 1er'!$G$821 -> 247060000 | H12: 206800000 | I12: 177500000 | J12: 419000000 | K12: 319240000 | L12: 547000000 | M12: 170000000 | N12: 169800000 | O12: 1180000000 | P12: 203700000 | Q12: 295000000 | R12: 329400000 | S12: 204000000 | T12: 111500000 | U12: 90070000 | V12: 244300000 | W12: 117500000 | X12: 1650400000 | Y12: 89600000 | Z12: 139800000 | AA12: 117500000 | AB12: 393475000 | AC12: =SUM(C12:AB12) -> 8598365000
A13: 9 | B13: Assainissement | F13: 60400000 | J13: 0 | M13: 0 | S13: 2000000 | U13: 45840000 | AC13: =SUM(C13:AB13) -> 108240000
B14: Eau | C14: 1.2596778e+09 | D14: 769920000 | E14: 1672720000 | F14: 1241100000 | G14: ='32 Cadre L ogiqueBfssam 1er'!$G$454 -> 1766200000 | H14: 445500000 | I14: 680629000 | J14: 310900000 | K14: 352300000 | L14: 555000000 | M14: 322000000 | N14: 713204000 | O14: 1000700000 | P14: 234160000 | Q14: 215000000 | R14: 449100000 | S14: 810000000 | T14: 592600000 | U14: 449254362 | V14: 588044000 | W14: 225600000 | X14: 225600000 | Y14: 1052800000 | Z14: 851640000 | AA14: 395140000 | AB14: 2160377000 | AC14: =SUM(C14:AB14) -> 1.9339166e+10
B15: Energie | C15: 1.8895168e+09 | D15: 1154880000 | E15: 2509080000 | F15: 1720500000 | G15: ='32 Cadre L ogiqueBfssam 1er'!$G$482 -> 10038000000 | H15: 1892000000 | I15: 3160000000 | J15: 683850000 | K15: 3519600000 | L15: 1998000000 | M15: 1475000000 | N15: 1069806000 | O15: 346000000 | P15: 351240000 | Q15: 237000000 | R15: 300000000 | S15: 530000000 | T15: 758110000 | U15: 2410768000 | V15: 882066000 | W15: 338400000 | X15: 338400000 | Y15: 1579200000 | Z15: 1277460000 | AA15: 592710000 | AB15: 3240565500 | AC15: =SUM(C15:AB15) -> 4.4292152e+10
B16: Produits pétroliers | F16: 4400000 | J16: 0 | M16: 0 | O16: 1346700000 | S16: 0 | AC16: =SUM(C16:AB16) -> 1351100000
A17: =+A13+1 -> 10 | B17: Affaires sociales | C17: 122110000 | D17: 270000000 | E17: 177100000 | F17: 97450000 | G17: ='32 Cadre L ogiqueBfssam 1er'!$G$396 -> 28000000 | H17: 326700000 | I17: 272500000 | J17: 133000000 | K17: 271500000 | L17: 403000000 | M17: 94500000 | N17: 128500000 | O17: 327000000 | P17: 90000000 | Q17: 154000000 | R17: 63480000 | S17: 168000000 | T17: 106200000 | U17: 231660000 | V17: 14750000 | W17: 21600011 | X17: 21500000 | Y17: 1670000 | Z17: 16500000 | AA17: 367100000 | AB17: 141000000 | AC17: =SUM(C17:AB17) -> 4048820011
A18: =A17+1 -> 11 | B18: Promotion de la femme et famille | C18: 71660000 | D18: 128600000 | E18: 219860000 | F18: 166800000 | G18: ='32 Cadre L ogiqueBfssam 1er'!$G$382 -> 342290000 | H18: 65670000 | I18: 182200000 | J18: 139000000 | K18: 311000000 | L18: 760558000 | M18: 76000000 | N18: 158200000 | O18: 263000000 | P18: 164800000 | Q18: 101000000 | R18: 41850000 | S18: 80000000 | T18: 125130000 | U18: 200760000 | V18: 144500000 | W18: 118400000 | X18: 3200000 | Y18: 137240000 | Z18: 119200000 | AA18: 179200000 | AB18: 198000000 | AC18: =SUM(C18:AB18) -> 4498118000
A19: =A18+1 -> 12 | B19: Culture | C19: 668270000 | D19: 430000000 | E19: 242050000 | F19: 405500000 | G19: ='32 Cadre L ogiqueBfssam 1er'!$G$340 -> 277600000 | H19: 352471680 | I19: 514000000 | J19: 360000000 | K19: 1021250000 | L19: 835000000 | M19: 311000000 | N19: 302000000 | O19: 1169000000 | P19: 258750000 | Q19: 148000000 | R19: 520000000 | S19: 6250000 | T19: 412200000 | U19: 609080000 | V19: 442000000 | W19: 765000000 | X19: 300000 | Y19: 192700000 | Z19: 193100000 | AA19: 284200000 | AB19: 1410200000 | AC19: =SUM(C19:AB19) -> 12129921680
A20: =A19+1 -> 13 | B20: Petites et Moyennes Entreprises | C20: 925840000 | D20: 105250000 | E20: 69110000 | F20: 77500000 | G20: ='32 Cadre L ogiqueBfssam 1er'!$G$862 -> 55000000 | H20: 83600000 | I20: 448000000 | J20: 250500000 | K20: 202500000 | L20: 289500000 | M20: 69500000 | N20: 889200000 | O20: 696500000 | P20: 18000000 | Q20: 6000000 | R20: 49000000 | S20: 0 | T20: 69200000 | U20: 452150000 | V20: 30100000 | W20: 160750000 | X20: 11700000 | Y20: 7200000 | Z20: 90500000 | AA20: 46000000 | AB20: 366040000 | AC20: =SUM(C20:AB20) -> 5468640000
B21: Economie Sociale | G21: ='32 Cadre L ogiqueBfssam 1er'!$G$882 -> 40000000
B22: Artisanat | G22: ='32 Cadre L ogiqueBfssam 1er'!$G$898 -> 20000000
A23: =A20+1 -> 14 | B23: Industries, Mines et Développement Technologique | C23: 86760000 | D23: 40300000 | E23: 202600000 | F23: 688450000 | G23: ='32 Cadre L ogiqueBfssam 1er'!$G$923 -> 211500000 | H23: 1160500000 | I23: 2225000000 | J23: 1612500000 | K23: 125800000 | L23: 398000000 | M23: 212000000 | N23: 378000000 | O23: 1707500000 | P23: 6000000 | Q23: 1000000 | R23: 89300000 | S23: 0 | T23: 283500000 | U23: 105900000 | V23: 50000000 | W23: 51900000 | X23: 300000000 | Y23: 42200000 | Z23: 2057700000 | AA23: 347100000 | AB23: 210020000 | AC23: =SUM(C23:AB23) -> 12593530000
A24: =A23+1 -> 15 | B24: Tourisme et Loisirs | C24: 13810000 | D24: 1340000000 | E24: 145050000 | F24: 1318200000 | G24: ='32 Cadre L ogiqueBfssam 1er'!$G$597 -> 442050000 | H24: 273900000 | I24: 502500000 | J24: 285000000 | K24: 87500000 | L24: 753354000 | M24: 422000000 | N24: 163000000 | O24: 1030000000 | P24: 306900000 | Q24: 115000000 | R24: 351500000 | S24: 0 | T24: 465400000 | U24: 441925000 | V24: 167000000 | W24: 607000000 | X24: 3000000 | Y24: 31100000 | Z24: 125200000 | AA24: 137040000 | AB24: 168800000 | AC24: =SUM(C24:AB24) -> 9696229000
A25: =A24+1 -> 16 | B25: Domaine affaires foncières | C25: 74470000 | D25: 136000000 | E25: 11500000 | F25: 10000000 | G25: ='32 Cadre L ogiqueBfssam 1er'!$G$736 -> 43400000 | H25: 159500000 | I25: 152000000 | J25: 19000000 | K25: 44250000 | L25: 342000000 | M25: 35000000 | N25: 8000000 | O25: 52000000 | P25: 224000000 | Q25: 10000000 | R25: 100000000 | S25: 26250000 | T25: 68600000 | U25: 29570000 | V25: 8200000 | W25: 65250000 | X25: 111000000 | Y25: 27100000 | Z25: 49000000 | AA25: 115250000 | AB25: 35000000 | AC25: =SUM(C25:AB25) -> 1956340000
A26: =A25+1 -> 17 | B26: Commerce | C26: 306294058 | D26: 3000000 | E26: 735000000 | F26: 1107000000 | G26: ='32 Cadre L ogiqueBfssam 1er'!$G$785 -> 440500000 | H26: 431200000 | I26: 95000000 | J26: 800000000 | K26: 633700000 | L26: 342000000 | M26: 44000000 | N26: 277664500 | O26: 5835700000 | P26: 85200000 | Q26: 43000000 | R26: 885300000 | S26: 209400000 | T26: 95000000 | U26: 255719540 | V26: 6500000 | W26: 1266200000 | X26: 200000 | Y26: 1043200000 | Z26: 356000000 | AA26: 946300000 | AB26: 729125000 | AC26: =SUM(C26:AB26) -> 16972203098
A27: =A26+1 -> 18 | B27: Transport | C27: 56450000 | D27: 7250000 | E27: 55500000 | F27: 36000000 | G27: ='32 Cadre L ogiqueBfssam 1er'!$G$971 -> 38550000 | H27: 1138500000 | I27: 171000000 | J27: 229500000 | K27: 157600000 | L27: 543000000 | M27: 24000000 | N27: 3200000 | O27: 963000000 | P27: 4250000 | Q27: 13000000 | R27: 2100000 | S27: 215000000 | T27: 115000000 | U27: 54750000 | V27: 4100000 | W27: 27000000 | X27: 800600000 | Y27: 45600000 | Z27: 50800000 | AA27: 79400000 | AB27: 509600000 | AC27: =SUM(C27:AB27) -> 5344750000
A28: =A27+1 -> 19 | B28: Poste et Télécommunication | C28: 33320000 | D28: 50000000 | E28: 120000000 | F28: 344020000 | G28: ='32 Cadre L ogiqueBfssam 1er'!$G$948 -> 320060000 | H28: 99880000 | I28: 151130000 | J28: 334100000 | K28: 313150000 | L28: 965000000 | M28: 74015000 | N28: 95000000 | O28: 276510000 | P28: 87900000 | Q28: 93030000 | R28: 3250000 | S28: 2000000 | T28: 141250000 | U28: 48250000 | V28: 34550000 | W28: 218250000 | X28: 200000 | Y28: 3040000 | Z28: 18500000 | AA28: 90250000 | AB28: 329200000 | AC28: =SUM(C28:AB28) -> 4245855000
A29: =A28+1 -> 20 | B29: Administration Territoriale, sécurité et maintien de l’ordre | C29: 158230000 | D29: 65000000 | E29: 270650000 | F29: 135170000 | G29: ='32 Cadre L ogiqueBfssam 1er'!$G$1024 -> 307660000 | H29: 99000000 | I29: 124000000 | J29: 658648000 | K29: 236200000 | L29: 542000000 | M29: 48000000 | N29: 276000000 | O29: 335350000 | P29: 72300000 | Q29: 2000000 | R29: 107600000 | S29: 0 | T29: 70200000 | U29: 307190000 | V29: 276000000 | W29: 298000000 | X29: 50700000 | Y29: 404700000 | Z29: 17000000 | AA29: 415900000 | AB29: 742500000 | AC29: =SUM(C29:AB29) -> 6019998000
A30: =A29+1 -> 21 | B30: Décentralisation et Développement Local | G30: ='32 Cadre L ogiqueBfssam 1er'!$G$1036 -> 40050000 | J30: 0 | M30: 178600000 | O30: 172800000 | Q30: 0 | R30: 10000000 | S30: 0 | AC30: =SUM(C30:AB30) -> 401450000
A31: =A30+1 -> 22 | B31: Forêt et faune | C31: 13810000 | D31: 159400000 | E31: 317435000 | F31: 86500000 | G31: ='32 Cadre L ogiqueBfssam 1er'!$G$622 -> 40000000 | H31: 56150000 | I31: 95500000 | J31: 158500000 | K31: 56000000 | L31: 134000000 | M31: 177800000 | N31: 59500000 | O31: 249250000 | P31: 52800000 | Q31: 103000000 | R31: 253900000 | S31: 190250000 | T31: 29500000 | U31: 39760000 | V31: 23400000 | W31: 31320000 | X31: 2600000 | Y31: 65430000 | Z31: 14000000 | AA31: 89800000 | AB31: 84600000 | AC31: =SUM(C31:AB31) -> 2584205000
A32: =A31+1 -> 23 | B32: Environnement et Protection de la Nature | C32: 43890000 | D32: 62000000 | E32: 300900000 | F32: 122150000 | G32: ='32 Cadre L ogiqueBfssam 1er'!$G$682 -> 441300000 | H32: 1111550000 | I32: 112500000 | J32: 143000000 | K32: 132300000 | L32: 657000000 | M32: 1825000000 | N32: 28900000 | O32: 5382000000 | P32: 36000000 | Q32: 197000000 | R32: 197862677 | S32: 800000 | T32: 611500000 | U32: 27860000 | V32: 26000000 | W32: 315500000 | X32: 102600000 | Y32: 52600000 | Z32: 651500000 | AA32: 266700000 | AB32: 116000000 | AC32: =SUM(C32:AB32) -> 12964412677
A33: =A32+1 -> 24 | B33: Habitat et Développement Urbain | C33: 750600000 | D33: 57000000 | E33: 8063000000 | F33: 544500000 | G33: ='32 Cadre L ogiqueBfssam 1er'!$G$718 -> 7627900000 | H33: 85800000 | I33: 214100000 | J33: 8475500000 | K33: 188000000 | L33: 670000000 | M33: 500000000 | N33: 540000000 | O33: 1818000000 | P33: 1422000000 | Q33: 752000000 | R33: 157750000 | S33: 2242750000 | T33: 982000000 | U33: 709400000 | V33: 577100000 | W33: 674000000 | X33: 67335528 | Y33: 22150000 | Z33: 41000000 | AA33: 57500000 | AB33: 1126850000 | AC33: =SUM(C33:AB33) -> 38366235528
A34: =A33+1 -> 25 | B34: Emploi et formation professionnelle | C34: 496245560 | D34: 403500000 | E34: 1219000000 | F34: 872000000 | G34: ='32 Cadre L ogiqueBfssam 1er'!$G$553 -> 1115020000 | H34: 871200000 | I34: 448000000 | J34: 950000000 | K34: 542630000 | L34: 765000000 | M34: 17400000 | N34: 198500000 | O34: 45000000 | P34: 211600000 | Q34: 226000000 | R34: 5400000 | S34: 110000000 | T34: 199000000 | U34: 82800000 | V34: 174900000 | W34: 22220000 | X34: 275000000 | Y34: 82950000 | Z34: 90000000 | AA34: 278000000 | AB34: 93500000 | AC34: =SUM(C34:AB34) -> 9794865560
A35: =A34+1 -> 26 | B35: Travail et Sécurité Sociale | C35: 34850000 | D35: 3000000 | E35: 72240000 | F35: 5400000 | G35: ='32 Cadre L ogiqueBfssam 1er'!$G$572 -> 6000000 | H35: 27500000 | I35: 105500000 | J35: 33500000 | K35: 16000000 | L35: 356400000 | M35: 300000000 | N35: 5900000 | O35: 711000000 | P35: 6800000 | Q35: 37400000 | R35: 702500000 | S35: 210000000 | T35: 10300000 | U35: 1650000 | V35: 4000000 | W35: 2020000 | X35: 200000 | Y35: 6550000 | Z35: 4500000 | AA35: 4500000 | AB35: 27000000 | AC35: =SUM(C35:AB35) -> 2694710000
A36: =A35+1 -> 27 | B36: Sport et éducation physique | C36: 120600000 | D36: 430000000 | E36: 105100000 | F36: 139500000 | G36: ='32 Cadre L ogiqueBfssam 1er'!$G$842 -> 100040000 | H36: 2401168000 | I36: 608100000 | J36: 547000000 | K36: 319240000 | L36: 985000000 | M36: 80000000 | N36: 830000000 | O36: 216000000 | P36: 203700000 | Q36: 100500000 | R36: 50200000 | S36: 71800000 | T36: 214500000 | U36: 111350000 | V36: 654000000 | W36: 465500000 | Y36: 2900000 | Z36: 103500000 | AA36: 832000000 | AB36: 456400000 | AC36: =SUM(C36:AB36) -> 10148098000
A37: =A36+1 -> 28 | B37: Recherche Scientifique et de l’Innovation | C37: 71280000 | D37: 95500000 | E37: 10060000 | F37: 68750000 | G37: ='32 Cadre L ogiqueBfssam 1er'!$G$756 -> 25050000 | H37: 115500000 | I37: 145700000 | J37: 374000000 | K37: 76934000 | L37: 984000000 | M37: 50000000 | N37: 35000000 | O37: 130000000 | P37: 53910000 | Q37: 31000000 | R37: 1062000000 | S37: 0 | T37: 53500000 | U37: 40488000 | V37: 35000000 | W37: 44000000 | X37: 710400000 | Y37: 3000000 | Z37: 30000000 | AA37: 84500000 | AB37: 66250000 | AC37: =SUM(C37:AB37) -> 4395822000
A38: =A37+1 -> 29 | B38: Enseignement supérieur | C38: 33400000 | D38: 150000000 | E38: 200000 | F38: 25000000 | G38: ='32 Cadre L ogiqueBfssam 1er'!$G$1043 -> 200000 | H38: 55000000 | I38: 29500000 | J38: 311000000 | K38: 120000000 | L38: 987000000 | M38: 46000000 | N38: 25000000 | O38: 342500000 | P38: 6000000 | Q38: 3000000 | R38: 58000000 | S38: 1000000 | T38: 104000000 | U38: 95600000 | V38: 25000000 | W38: 15500000 | X38: 450000000 | Y38: 22600000 | Z38: 13000000 | AA38: 1062000000 | AB38: 82750000 | AC38: =SUM(C38:AB38) -> 4063250000
A39: =A38+1 -> 30 | B39: Economie, planification et aménagement | AC39: =SUM(C39:AB39) -> 0
A40: =A39+1 -> 31 | B40: Communication | C40: 56240000 | D40: 150000000 | E40: 0 | F40: 6500000 | G40: ='32 Cadre L ogiqueBfssam 1er'!$G$993 -> 105000000 | H40: 200750000 | I40: 77500000 | J40: 83800000 | K40: 70150000 | L40: 872000000 | N40: 250000000 | O40: 0 | P40: 32000000 | Q40: 53000000 | R40: 0 | S40: 0 | T40: 6500000 | U40: 56740000 | V40: 261000000 | W40: 67000000 | X40: 200000 | Y40: 1800000 | Z40: 125500000 | AA40: 63500000 | AB40: 17900000 | AC40: =SUM(C40:AB40) -> 2557080000
A41: =A40+1 -> 32 | B41: VIH | C41: 0 | D41: 0 | E41: 0 | F41: 0 | G41: 0 | H41: 0 | J41: 0 | K41: 0 | N41: 0 | O41: 0 | P41: 0 | Q41: 0 | R41: 0 | S41: 5750000 | T41: 0 | U41: 0 | V41: 0 | W41: 0 | X41: 0 | Y41: 0 | Z41: 0 | AA41: 0 | AB41: 0 | AC41: =SUM(C41:AB41) -> 5750000
...

Sheet 64 bis Bfsamm 1er
B2: 31. Tableau de synthèse des microprojets prioritaires par village
D4: Rang des projets sociaux prioritaires | I4: Rang des projets économiques prioritaires | L4: Le projet prioritaire sélectionné par chaque village
B5: N° | C5: Village/Es pace urbain | D5: 1er | E5: 2ème | F5: 3ème | G5: 4ème | H5: 5ème | I5: 1er | J5: 2ème | K5: 3ème | L5: Intitulé du projet | M5: Coût estimatif | N5: Justification de la sélection
B6: 1 | C6: MEDJO I | D6: Aménagement de 5km de la route principale de Medjo I : Axe : Medjo I/ INO → Plaque | E6: Construction d’un bâtiment de trois salles de classes à l’école maternelle de Medjo I | F6: Affectation de deux (2) enseignants pour l’Ecole Publique de Medjo I | G6: Affectation de quatre (4) enseignants pour la maternelle de Medjo I | H6: Création d’un CETIC à Medjo I | I6: Mise en place d’un point de distribution des intrants agricoles et semences améliorées | J6: Construction d’un marché périodique | K6: Formations des femmes et jeunes aux AGR | L6: Aménagement de 5km de la route principale de Medjo I : Axe : Medjo I/ INO → Plaque
C7: Montant | D7: 25000000 | E7: 30000000 | F7: 5000 | G7: 5000 | H7: 5000 | I7: 5000 | M7: 25000000
B8: 2 | C8: TCHO | D8: Electrification du village à partir de la triphasée de Tougnié pour utilisation domestique sur 3 Km. Itinéraire : Tougniè→carre four TAA Claude | E8: Reprofilage de 5km de l’axe routier pont TESSEPE→marché Kouvou passant par l’école publique | F8: Reprofilage de 3km de l’axe TANGUELE →carrefour TACLO—marché Kouvou | G8: Aménagement de l’axe TANGUELE→ TESSEPE sur 4 Km | H8: Construction d’un ouvrage de franchisseme nt sur l’axe TAGUELE Pont TESSEPE avant le carrefour Taguele | I8: Mise en place d’un point de distribution des intrants agricoles et semences améliorées | J8: Construction d’un marché périodique | K8: Formations des femmes et jeunes de Ndemsiem aux AGR | L8: Electrification du village à partir de la triphasée de Tougnié pour utilisation domestique sur 3 Km. Itinéraire : Tougniè→carre four TAA Claude | N8: Difficulté à exécuter des activités génératrice de revenus et de transformation des produits agricoles
D9: 50000000 | E9: 12500000 | F9: 7500000 | G9: 100000000 | H9: 30000000 | M9: 50000000
B10: 3 | C10: MVOUTS A’A | D10: Construction de 05 blocs de latrines dans les Ecoles Publiques de Mvoutsa'a | E10: Construction de 02 forages munis d’une pompe à motricité humaine à MVOUTSA’A. Quartier Takoté et Quartier Ndzemna | F10: Construction d’un forage muni d’une pompe à motricité humaine à MVOUTSA’A. Quartier Bougan | G10: Réhabilitation du forage en panne à MVOUTSA’A derrière le marché | H10: Extension du réseau électrique dans les quartiers Bougan, Dzemna et Tsetsa de Mvoutsa’a 6 Km sur l’axe Kuvou pour utilisation domestique | I10: Aménagement de 300m de route menant aux carrières de pierres et latérites à MVOUTSA’A. Axe DZEMNA-carrière | J10: Aménagement de 400m de route menant aux carrières de pierres et latérites à MVOUTSA’A. AXE : route des fermiers - BOUGAM | K10: n de 40 comptoirs dans le hangar du marché à MVOUTSA’Constructio A lieu dit Marché KOUVOU | L10: Construction de 05 blocs de latrines dans les Ecoles Publiques de Mvoutsa'a | N10: Assainissement « Hygiène et salubrité » pour les tout petits de l’école primaire
D11: 10000000 | E11: 9000000 | F11: 9000000 | G11: 2000000 | H11: 25000000 | I11: 100000 | J11: 150000 | K11: 10000000 | M11: 10000000
B12: 4 | C12: NDEMSIE M | D12: Electrification du village à partir de la triphasée de Tougnié pour utilisation domestique sur 3 Km. Itinéraire : Tougniè→carre four TAA Claude Itinéraire : Ndemsiem / Axe Batoukop – Carrefour Deffo Taghi | E12: Reprofilage de 06 km de route à Ndemsiem axe central Batoukop – Ndiembou par Kapti. Axe : Ndemsiem/ axe central Batoukop – Ndiembou par Kapti | F12: Construction d’un ouvrage de franchisseme nt à Ndemsiem | G12: construction d’un forage muni d’une pompe à motricité humaine à Ndemsiem au carrefour Tchouofé | H12: Construction d’un forage muni d’une pompe à motricité humaine à Ndemsiem au carrefour Tekou Sindze | I12: Mise en place d’un point de distribution des intrants améliorés d’élevage (souches améliorées de porcs, chèvres, lapins et équipements) à Ndemsiem | J12: Appui à l’organisation des producteurs en sociétés coopératives à Ndemsiem en intrants agricoles au niveau des sociétés coopératives | K12: Formations des femmes et jeunes aux AGR | L12: Electrification du village Ndemsiem à partir de la triphasée de Batoukop sur 5 Km pour usage domestique. Itinéraire : Ndemsiem / Axe Batoukop – Carrefour Deffo Taghi | N12: Difficulté à exécuter des activités génératrice de revenus et de transformation des produits agricoles
D13: 20000000 | E13: 15000000 | F13: 30000000 | G13: 9000000 | H13: 9000000 | M13: 20000000
B14: 5 | C14: NDIENGD AM II | D14: Construction d’un bâtiment de deux salles de classes à de l’école maternelle de NDIENGDAM II | E14: Extension du réseau électrique à NDIENGDAM II bloc 3 pour utilisation domestique sur 3,5 Km. Du carrefour rembleur à Toulouse | F14: Construction d’un forage muni d’une pompe à motricité humaine à NDIENGDAM II – Bloc 1 au niveau du Carrefour rembleur | G14: Construction d’un Pont derrière Total Ndiengdam | H14: Construction d’un forage à NDIENGDAM II-Bloc 3 à Toulouse et à Bloc 6 après | I14: Mise en place d’un point de distribution des intrants agropastorau x améliorés | J14: Construction d’un marché périodique | K14: Formations des femmes et jeunes aux AGR | L14: Construction d’un bâtiment de deux salles de classes à de l’école maternelle de NDIENGDAM II | N14: Difficulté à avoir
D15: 20000000 | E15: 20000000 | F15: 9000000 | G15: 30000000 | H15: 18000000 | M15: 20000000
B16: 6 | C16: BANEFO | D16: Extension du réseau CDE de BANEFO du quartier BANEFO 1er à partir de Sacha 4 Km | E16: Finalisation du projet de captage en cours à BANEFO du quartier BANEFO 1er 5 Km | F16: Remplacement du transformateu r électrique de BANEFO | G16: Extension du réseau électrique dans BANEFO sur l’axe Marché kwogou 7 Km | H16: Construction des ouvrages de franchisseme nt. BANEFO pont chefferie | I16: Mise en place d’un point de distribution des intrants agropastorau x améliorés | J16: Construction d’un marché périodique | K16: Formations des femmes et jeunes aux AGR | L16: Extension du réseau CDE de BANEFO du quartier BANEFO 1er à partir de Sacha sur 4 Km | N16: Difficulté à exécuter des activités génératrice de revenus et de transformation des produits agricoles
D17: 10000000 | E17: 5000000 | F17: 5000000 | G17: 10000000 | H17: 30000000 | M17: 10000000
B18: 7 | C18: NDIENGD AM I | D18: Construction de 02 bloc de latrines dans l’école Publique de Vava, | E18: Création d’un centre de santé à NDIENGDAM 1 | F18: Création d’un CES à Ndiangdam I | G18: Construction d’une clôture à l’école publique de NDIENGDAM 1 | H18: Construction d’un bâtiment de trois salles de classe à l’école publique de NDIENGDAM 1. | I18: Extension du réseau AES/Sonel à NDIENGDAM 1 sur 3,5 Km pour utilisation domestique. du carrefour Lycée à VAVCVAC | J18: Construction d’un marché périodique | K18: Formations des femmes et jeunes aux AGR | L18: Construction de 02 blocs de latrines dans l’école Publique de Vava, | N18: Hygiène et salubrité pour les tout petits de l’école primaire
D19: 10000000 | E19: 50000 | F19: 50000 | G19: 10000000 | H19: 30000000 | M19: 10000000
B20: 8 | C20: MEDJO II | D20: Extension du réseau AES/Sonel dans MEDJO 2 pour utilisation domestique et économique sur 4 Km du marché NKAM à Nkounkong | E20: Aménagemen t de la route dans MEDJO 2 sur 5 Km de NKAM à Mbougam | F20: Extension du réseau du captage d’eau de MEDJO 2 avec 03 bornes fontaines sur 03 Km pour les quartiers Seh, Doumguem , Kountié | G20: Construction des ouvrages de franchisseme nt de Nsa – Ba’a | H20: Réparation des 03 bornes fontaines en panne à MEDJO 2 pour les quartiers Fondje-Aaron, Wafo- Fam, Defomiafang | I20: Mise en place d’un point de distribution des intrants agropastorau x améliorés | J20: Construction d’un marché périodique | K20: Formations des femmes et jeunes aux AGR | L20: Extension du réseau AES/Sonel dans MEDJO 2 pour utilisation domestique et économique sur 4 Km du marché NKAM à Nkounkong | N20: Difficulté à exécuter des activités génératrice de revenus et de transformation des produits agricoles
D21: 10000000 | E21: 2500000 | F21: 5000000 | G21: 30000000 | H21: 10000000 | M21: 10000000
B22: 9 | C22: MELAM I | D22: Construction d’un captage pour un troisième bac de recueillement pour renforcer la capacité du château | E22: Création d’une école primaire maternelle bilingue à MELAM 1 | F22: Création d’un CES à MELAM 1 | G22: Création d’un CETIC à MELAM 1 | H22: Construction des ouvrages de franchisseme nt de Lom à MELAM 1 | I22: Construction d’un centre d’épuration des déchets spéciaux | J22: Mise en place d’un point de distribution des intrants agropastorau x améliorés | K22: Constructio n d’un marché périodique | L22: Construction d’un centre d’épuration des déchets spéciaux | N22: Difficulter à assainir la commune
D23: 10000000 | E23: 50000 | F23: 50000 | G23: 50000 | H23: 30000000 | I23: 10000000 | M23: 10000000
B24: 10 | C24: FAMCEP | D24: Construction d’un forage à FAMCEP au Lycée | E24: Construction d’un forage à FAMCEP au quartier Dagne | F24: Construction d’un forage à FAMCEP au quartier Gozet (Ngouodzé) | G24: Construction d’un puit busé avec château | H24: Reprofilage de l’axe Dangne qui relie FAMCEP à Mvoutsa’a sur 2 Km | I24: Extension du réseau AES/SONEL dans FAMCEP | J24: Mise en place d’un point de distribution des intrants agropastorau x améliorés | K24: Constructio n d’un marché périodique | L24: Construction d’un forage à FAMCEP au Lycée | N24: Difficulté d’avoir accès à l’eau potable dans le village
D25: 9000000 | E25: 9000000 | F25: 9000000 | G25: 5000000 | H25: 2000000 | M25: 9000000
B26: 11 | C26: NDIENGS O II | D26: Construction et équipement d’un bâtiment de deux salles de classe à l’école publique de Ndiengso II | E26: Construction de 1 forage à la chefferie au niveau du poteau 41 | F26: Construction de l’ouvrage de franchissement de Totchoum en contrebas de la présente structure de la Mairie | G26: Construction de 01 bloc de latrines dans l’école Publique de Ndiengso II | H26: Construction d’1 puits busé avec château au stade de Ndiengso II, | I26: Reprofilage de l’axe de commune au poste de transformateu r sur 3km | J26: Mise en place d’un point de distribution des intrants agropastorau x améliorés | L26: Construction et équipement d’un bâtiment de deux salles de classe à l’école publique de Ndiengso II | N26: Difficulté d’accès aux infrastructures de bases
D27: 32000000 | E27: 9000000 | F27: 25000000 | G27: 5000000 | H27: 9000000 | M27: 32000000
D28: Extension du réseau électrique sur 03 Km pour utilisation domestique du Carrefour Fô Taghe à Ngawa en passant par l’ancien pont | E28: Construction d’un d’1 puits busé avec château à KOUEKONG niveau du marché | F28: Construction d’un bâtiment de deux salles de classe à l’école maternelle de Kouékong | G28: Equipement d’un bâtiment de deux salles de classe à l’école maternelle de Kouékong | H28: Construction d’un d’1 puits busé avec château à KOUEKONG niveau de l’EP | I28: Construction du marché de KOUEKONG, | J28: Construction d’un magasin de stockage des vivres frais | K28: Mise en place d’un point de distribution des intrants agropastora ux améliorés | L28: Construction du marché de KOUEKONG, | N28: Difficulté d’évacuation des produits agricole et de mener les AGR
B29: 12 | C29: KOUEKO NG | D29: 12000000 | E29: 9000000 | F29: 32000000 | G29: 32000000
B30: 13 | C30: NJINGA I | D30: Construction et équipement d’un bâtiment de deux salles de classe à l’école publique de NJINGA I | E30: Réhabilitation du forage1 non fonctionnel de Njinga I après le carrefour CETIC | F30: Réhabilitation du forage non fonctionnel de Njinga I au niveau de l’Eglise Evangélique | G30: Création d’un centre secondaire d’Etat Civil à Njinga I | H30: Repofilage de l’axe principal famleng-Ndiangdam I sur 2 km | I30: Construction du marché de à sacta | J30: Construction d’un magasin de stockage des vivres frais | K30: Mise en place d’un point de distribution des intrants agropastora ux améliorés | L30: Construction et équipement d’un bâtiment de deux salles de classe à l’école publique de NJINGA | N30: Difficulté d’accès à une éducation de qualité
D31: 32000000 | E31: 5000000 | F31: 5000000 | G31: 9000000 | H31: 6000000 | M31: 32000000
B32: 14 | C32: BATOUK OP | D32: Extension du réseau électrique sur 03 Km pour utilisation domestique du Carrefour Fô Taghe à Ngawa en passant par l’ancien pont | E32: Reprofilage de l’axe pont Tchienchueppont demsiem sur 3 K m | F32: Reprofilage de l’axe carrefour Tawembe Deffo Tietie - route allant à Tayim (1 km) | G32: Construction d’ 1 puits busé avec château à Tsémewéen | H32: Construction et équipement d’un poste agricole à Batoukop au quartier koufouet | I32: Extension du le réseau électrique sur une distance de de 500 m.Axe Tintchuet à Deffo Nje sur | J32: Extension du le réseau électrique sur 500m axe - carrefour Tawembe Deffo au domicile Deffo Paul | K32: Mise en place d’un point de distribution des intrants agropastora ux éléveurs | L32: Extension du réseau électrique sur une distance de 1 km sur l’axe :Tintchuet au pont à la limite de Ndemsiem sur 1 Km | N32: Difficulté à mener les activités génératrice de revenus.
D33: 5000000 | E33: 1500000 | F33: 1500000 | G33: 9000000 | H33: 26000000 | M33: 5000000
B34: 15 | C34: BANENG O VILLAGE III | D34: Création d’un CES dans Banengo village III | E34: Extension du réseau CDE dans le village | F34: Création d’une école maternelle et primaire publique dans le village | G34: Création et équipement d’un comité de vigilance (torches à longue portée, clairons, matraque, paires de menottes, etc) dans le village | H34: Extension du réseau dans le village | I34: Construction d’un marché à Banengo Village III, au carrefour TAMA | J34: Construction du Pont derrière le Collège de la Cité ; | K34: Mise en place d’un point de distribution des intrants agropastora ux améliorés | L34: Construction d’un marché à Banengo Village III, au carrefour TAMA | N34: Difficulté à accéder aux infrastructures marchandes et à mener les activités génératrices de revenus
D35: 50000 | E35: 10000000 | F35: 50000000 | G35: 2000000 | I35: 20000000 | M35: 20000000
B36: 17 | C36: MELAM II | D36: Extension du réseau électrique sur 3 km de Kouofo jusqu’à chez Deffo Tamghe | E36: Construction et équipement d’un bâtiment de deux salles de classes à l’Ecole maternelle publique de Kouopfo | F36: Equipement de l’Ecole publique de Kouopfo en 40 tables bancs | G36: Construction de la clôture du CSI de Mélam | H36: Achat d’un groupe électrogène pour la station de pompage de l’adduction d’eau potable de Melam 2 | I36: Construction d’un hangar au marché de Kam | J36: Mise en place d’un point de distribution des intrants agropastorau x améliorés | L36: Extension du réseau électrique sur 3 km de Kouofo jusqu’à chez Deffo Tamghe | N36: Difficulté à mener les activités génératrice de revenus.
D37: 10000000 | E37: 30000000 | F37: 2000000 | G37: 5000000 | H37: 300000 | I37: 10000000 | L37: 10000000 | M37: 10000000
B38: 18 | C38: NDIENGS O I | D38: Réhabilitation de 03 points d’eau dans le village à : Kaptue(Simfo), Mela (carrefour TAMO Claude,Ecole Publique) | E38: Création d’un Centre de santé intégré à NDiengso I | F38: Création d’une section anglophone à l’EP de Badiengso à NDIENGSO I | G38: Construction de 4 nouvelles salles de classe à l’EP de Badiengso | H38: Construction de 2 blocs administratifs bureaux à l’EP de Badiengso I | I38: Construction d’un marché à Ndiengso I | J38: Création d’un site touristique à Ndiengso I | K38: Mise en place d’un point de distribution des intrants agropastora ux améliorés | L38: Réhabilitation de 03 points d’eau dans le village à : Kaptue(Simfo), Mela (carrefour TAMO Claude, Ecole Publique) | N38: Difficulté d’accès à l’eau potable
D39: 1000000 | E39: 50000 | F39: 50000 | G39: 40000000 | H39: 32000000 | I39: 10000000 | J39: 20000000 | M39: 1000000
B40: 19 | C40: NJINGA II | D40: Création et construction d’un bloc de deux salles de classe dans l’ Ecole Publique et maternelle bilingue à Njingha 2 | E40: Construction de 01 bloc de latrines dans l’école Publique de Njingah II | F40: Construction de 3 dos d’âne sur le long trait de la Nationale Bafoussam Foumban sur 01 Km de l’usine SOCAO jusqu’à Batoula | G40: Extension du réseau CDE sur toutes les rues du village | H40: Création de 5 points d’eau : -au CSI, -à l’entrée de Sob Guabi, - à l’entrée lycée, -vers chez Sob Foko, -vers chez Agip) | I40: Extension du réseau électrique dans toutes les rues du village | J40: Mise en place d’un point de distribution des intrants agricoles et semences améliorées en vue de l’amélioration des la productivité | K40: Mise en place d’un point de distribution des intrants améliorés d’élevage (souches améliorées de porcs, chèvres, lapins et équipement s) à Njinga II | L40: Extension du réseau électrique dans toutes les rues du village | N40: Difficulté à mener les activités génératrice de revenus.
D41: 32000000 | E41: 5000000 | F41: 1000000 | G41: 10000000 | H41: 10000000 | I41: 10000000 | M41: 10000000
B42: 20 | C42: TOMDJO | D42: Construction d’ 01 ouvrage de franchissement « Pont »derrièr e l’EP de Tomdjo | E42: Construction et d’équipement de 06 salles de classe à l’EP de Tomdjo | F42: Construction d’un bloc latrine à l’Ecole Publique primaire et maternelle bilingue de Tomdjo (en cours) | G42: Réfection des dos d’âne du Carrefour Tougniet | H42: Construction d’un bloc latrine à l’Ecole Publique primaire et maternelle bilingue de Tomdjo (en cours) | I42: Construction du marché de Tougniet | J42: Mise en place d’un point de distribution des intrants agricoles et semences améliorées en vue de l’amélioration des la productivité | K42: Constructio n d’une barrière de pluie | L42: Construction d’ 01 ouvrage de franchissement « Pont »derrièr e l’EP de Tomdjo | N42: Difficulté d’évacuation des produits agricoles
...
